<?xml version="1.0"?>
<robot name="summit" xmlns:xacro="http://www.ros.org/wiki/xacro">

  <!-- Import all Gazebo-customization elements, including Gazebo colors -->
  <xacro:include filename="summit.gazebo" />
<!--  <xacro:include filename="kinect.xacro" /> -->
  <xacro:include filename="laser.xacro" /> 
  <!-- Robot mechanical and motor parameters -->
  <xacro:property name="PI" value="3.1415926535897931"/>
  <xacro:property name="wheel_offset_x" value="0.185" />    <!-- x,y,z in base_footprint CS -->
  <xacro:property name="wheel_offset_y" value="0.105" />
  <xacro:property name="wheel_offset_z" value="0.0" />
  <xacro:property name="steer_joint_effort_limit" value="100.0" />
  <xacro:property name="steer_joint_velocity_limit" value="3.0" />
  <xacro:property name="steer_joint_damping" value="0.2" />
  <xacro:property name="steer_joint_friction" value="0.1" />
  <xacro:property name="steer_mechanical_reduction" value="100.0" />

  <xacro:property name="wheel_joint_effort_limit" value="100.0" />
  <xacro:property name="wheel_joint_damping" value="0.0" />
  <xacro:property name="wheel_joint_friction" value="0.0" />

  <xacro:property name="wheel_joint_velocity_limit" value="200.0" />
  <xacro:property name="wheel_mechanical_reduction" value="1.0" />
  <xacro:property name="wheel_width" value="0.175" />
  <xacro:property name="ptz_joint_effort_limit" value="100.0" />
  <xacro:property name="ptz_joint_velocity_limit" value="100.0"/>
  <xacro:property name="ptz_joint_friction" value="0.1" />
  <xacro:property name="ptz_joint_damping" value="0.1" />
  <xacro:property name="ptz_mechanical_reduction" value="1.0" />

  <xacro:property name="cam_px" value="-0.087" />
	<xacro:property name="cam_py" value="-0.0125" />
	<xacro:property name="cam_pz" value="0.2870" />
	<xacro:property name="cam_or" value="0" />
	<xacro:property name="cam_op" value="0" />
  <xacro:property name="cam_oy" value="0" />


  <!-- BASE FOOTPRINT -->

  <!-- base_footprint is a fictitious link(frame) that is on the ground right below base_link origin,
             navigation stack depends on this frame -->
  <link name="base_footprint">

      <visual>
          <origin xyz="0 0 0" rpy="0 0 0" />
          <geometry>
             <box size="0.001 0.001 0.001" />
          </geometry>
      </visual>

      <collision>
          <origin xyz="0 0 0.0" rpy="0 0 0" />
          <geometry>
            <box size="0.001 0.001 0.001" />
         </geometry>
     </collision>
  </link>

  <joint name="base_footprint_joint" type="fixed">
     <!--NB: While you would think this would make it go up, it is oddly reversed.
      This moves the joint to 0,0,0 where we want it for rviz, etc. -->
     <!-- origin xyz="0 0 0.130" rpy="0 0 0" / -->
     <origin xyz="0 0 0.050" rpy="0 0 0"/>
     <parent link="base_footprint"/>
     <child link="base_link" />
  </joint>

  <!-- BASE_LINK (RED) -->
  <link name="base_link">
    <inertial>
      <mass value="6.5" />
      <origin xyz="0 0 0" />
      <inertia  ixx="0.21805" ixy="0.0"  ixz="-0.001"  iyy="0.33677"  iyz="0.0"  izz="0.20511" />
    </inertial>
    <visual>
       <origin xyz="0 0 0" rpy="0 0 0" />
       <geometry>
	     <mesh filename="package://summit_deskribapena/meshes/summit_chassis.dae"/>
       </geometry>
    </visual>
    <collision>
       <origin xyz="0 0 0.06" rpy="0 0 0 " />
       <geometry>
         <mesh filename="package://summit_deskribapena/meshes/summit_chassis.dae"/>
	     <!-- box size = "0.56 0.4 0.2"/ -->
       </geometry>
    </collision>
  </link>

<!-- DIRECTION BACK LEFT         -->
<!-- =========================== -->
  <link name="back_left_wheel_dir">
    <inertial>
      <mass value="0.1" />
      <!-- center of mass (com) is defined w.r.t. link local coord system -->
      <origin xyz="0 0 0" />
      <inertia  ixx="0.01" ixy="0.0"  ixz="0.0"  iyy="0.01"  iyz="0.0"  izz="0.01" />
    </inertial>
    <visual>
       <!-- visual origin is defined w.r.t. link local coordinate system -->
       <origin xyz="0 0 0" rpy="0 0 0" />
       <geometry>
         <cylinder radius="0.015" length="0.025"/>
         <!-- mesh filename="package://summit_deskribapena/meshes/wheel_axis.dae"/-->
       </geometry>
    </visual>
    <collision>
       <!-- collision origin is defined w.r.t. link local coord. system -->
       <origin xyz="0 0 0" rpy="0 0 0 " />
       <geometry>
         <cylinder radius="0.015" length="0.025"/>
       </geometry>
    </collision>
  </link>

  <joint name="joint_back_left_wheel_dir" type="fixed">
    <parent link="base_link"/>
    <child link="back_left_wheel_dir"/>
    <origin xyz="-${wheel_offset_x} ${wheel_offset_y} 0" rpy="0 0 0" />
    <axis xyz="0 0 1" rpy="0 0 0" />
    <limit effort="${steer_joint_effort_limit}" velocity="${steer_joint_velocity_limit}" lower="-0.7854" upper="0.7854"/>
    <joint_properties damping="${steer_joint_damping}" friction="{steer_joint_friction}"/>
  </joint>

  <transmission name="joint_blw_trans_dir">
	<type>transmission_interface/SimpleTransmission</type>
    <joint name="joint_back_left_wheel_dir">
      <hardwareInterface>hardware_interface/EffortJointInterface</hardwareInterface>
    </joint>
    <actuator name="joint_blw_motor_dir">
	    <hardwareInterface>EffortJointInterface</hardwareInterface>
      <mechanicalReduction>${steer_mechanical_reduction}</mechanicalReduction>
	  <!-- motorTorqueConstant>1</motorTorqueConstant -->
	</actuator>
  </transmission>


  <!-- BACK LEFT WHEEL -->
  <link name="back_left_wheel">
    <inertial>
      <mass value="1.023" />
      <origin xyz="0 0 0" />
      <inertia  ixx="0.0027" ixy="0.0"  ixz="0.0"  iyy="0.0039"  iyz="0.0"  izz="0.0027" />
    </inertial>
    <visual>
       <origin xyz="0 0 0" rpy="0 0 0" />
       <geometry>
	     <mesh filename="package://summit_deskribapena/meshes/wheel.dae"/>
       </geometry>
        <material name="grey">
             <color rgba="0.5 0.5 0.5 1"/>
        </material>
    </visual>
    <collision>
       <origin xyz="0 0 0" rpy="0 0 0" />
       <geometry>
         <mesh filename="package://summit_deskribapena/meshes/wheel.dae"/>
       </geometry>
    </collision>
  </link>

  <joint name="joint_back_left_wheel" type="continuous">
    <parent link="back_left_wheel_dir"/>
    <child link="back_left_wheel"/>
    <origin xyz="0.0 0.060 0" rpy="0 0 0" />
    <axis xyz="0 1 0" rpy="0 0 0" />
    <limit effort="${wheel_joint_effort_limit}" velocity="${wheel_joint_velocity_limit}"/>
    <joint_properties damping="${wheel_joint_damping}" friction="{wheel_joint_friction}"/>
  </joint>

  <transmission name="joint_blw_trans">
	 <type>transmission_interface/SimpleTransmission</type>
     <joint name="joint_back_left_wheel">
       <hardwareInterface>hardware_interface/VelocityJointInterface</hardwareInterface>
     </joint>
     <actuator name="joint_blw_motor">
	    <!-- hardwareInterface>VelocityJointInterface</hardwareInterface-->
        <mechanicalReduction>${wheel_mechanical_reduction}</mechanicalReduction>
     	<!--motorTorqueConstant>1</motorTorqueConstant-->
	 </actuator>
  </transmission>

<!-- DIRECTION BACK RIGHT        -->
<!-- =========================== -->
  <link name="back_right_wheel_dir">
    <inertial>
      <mass value="0.1" />
      <!-- center of mass (com) is defined w.r.t. link local coord system -->
      <origin xyz="0 0 0" />
      <inertia  ixx="0.01" ixy="0.0"  ixz="0.0"  iyy="0.01"  iyz="0.0"  izz="0.01" />
    </inertial>
    <visual>
       <!-- visual origin is defined w.r.t. link local coordinate system -->
       <origin xyz="0 0 0" rpy="0 0 0" />
       <geometry>
         <cylinder radius="0.015" length="0.025"/>
       </geometry>
    </visual>
    <collision>
       <!-- collision origin is defined w.r.t. link local coord. system -->
       <origin xyz="0 0 0" rpy="0 0 0 " />
       <geometry>
         <cylinder radius="0.015" length="0.025"/>
       </geometry>
    </collision>
  </link>

  <joint name="joint_back_right_wheel_dir" type="fixed">
    <parent link="base_link"/>
    <child link="back_right_wheel_dir"/>
    <origin xyz="-${wheel_offset_x} -${wheel_offset_y} 0" rpy="0 0 0" />
    <axis xyz="0 0 1" rpy="0 0 0" />
    <limit effort="${steer_joint_effort_limit}" velocity="${steer_joint_velocity_limit}" lower="-0.7854" upper="0.7854"/>
    <joint_properties damping="${steer_joint_damping}" friction="{steer_joint_friction}"/>
  </joint>

  <transmission name="joint_brw_trans_dir">
	<type>transmission_interface/SimpleTransmission</type>
    <joint name="joint_back_right_wheel_dir">
      <hardwareInterface>hardware_interface/EffortJointInterface</hardwareInterface>
    </joint>
    <actuator name="joint_brw_motor_dir">
	  <hardwareInterface>EffortJointInterface</hardwareInterface>
      <mechanicalReduction>${steer_mechanical_reduction}</mechanicalReduction>
	  <!-- motorTorqueConstant>1</motorTorqueConstant -->
	</actuator>
  </transmission>


  <!-- BACK RIGHT WHEEL -->
  <link name="back_right_wheel">
    <inertial>
      <mass value="1.023" />
      <origin xyz="0 0 0" />
      <inertia  ixx="0.0027" ixy="0.0"  ixz="0.0"  iyy="0.0039"  iyz="0.0"  izz="0.0027" />
    </inertial>
    <visual>
       <origin xyz="0 0 0" rpy="0 0 0" />
       <geometry>
         <mesh filename="package://summit_deskribapena/meshes/wheel.dae"/>
       </geometry>
        <material name="grey">
                <color rgba="0.5 0.5 0.5 1"/>
        </material>
    </visual>
    <collision>
       <origin xyz="0 0 0" rpy="0 0 0" />
       <geometry>
         <mesh filename="package://summit_deskribapena/meshes/wheel.dae"/>
       </geometry>
    </collision>
  </link>

  <joint name="joint_back_right_wheel" type="continuous">
    <parent link="back_right_wheel_dir"/>
    <child link="back_right_wheel"/>
    <origin xyz="0.0 -0.060 0" rpy="0 0 0" />
    <axis xyz="0 1 0" rpy="0 0 0" />
    <limit effort="${wheel_joint_effort_limit}" velocity="${wheel_joint_velocity_limit}"/>
    <joint_properties damping="${wheel_joint_damping}" friction="{wheel_joint_friction}"/>
  </joint>

  <transmission name="joint_brw_trans">
	 <type>transmission_interface/SimpleTransmission</type>
     <joint name="joint_back_right_wheel">
       <hardwareInterface>hardware_interface/VelocityJointInterface</hardwareInterface>
     </joint>
     <actuator name="joint_brw_motor">
	    <hardwareInterface>VelocityJointInterface</hardwareInterface>
        <mechanicalReduction>${wheel_mechanical_reduction}</mechanicalReduction>
     	<!-- motorTorqueConstant>1</motorTorqueConstant -->
	 </actuator>
  </transmission>

<!-- DIRECTION FORWARD LEFT      -->
<!-- =========================== -->

  <link name="front_left_wheel_dir">
    <inertial>
      <mass value="0.1" />
      <!-- center of mass (com) is defined w.r.t. link local coord system -->
      <origin xyz="0 0 0" />
      <inertia  ixx="0.01" ixy="0.0"  ixz="0.0"  iyy="0.01"  iyz="0.0"  izz="0.01" />
    </inertial>
    <visual>
       <!-- visual origin is defined w.r.t. link local coordinate system -->
       <origin xyz="0 0 0" rpy="0 0 0" />
       <geometry>
         <cylinder radius="0.015" length="0.025"/>
       </geometry>
    </visual>
    <collision>
       <!-- collision origin is defined w.r.t. link local coord. system -->
       <origin xyz="0 0 0" rpy="0 0 0 " />
       <geometry>
         <cylinder radius="0.015" length="0.025"/>
       </geometry>
    </collision>
  </link>

  <joint name="joint_front_left_wheel_dir" type="revolute">
    <parent link="base_link"/>
    <child link="front_left_wheel_dir"/>
    <origin xyz="${wheel_offset_x} ${wheel_offset_y} 0" rpy="0 0 0" />
    <axis xyz="0 0 1" rpy="0 0 0" />
    <limit effort="${steer_joint_effort_limit}" velocity="${steer_joint_velocity_limit}" lower="-0.7854" upper="0.7854"/>
    <joint_properties damping="${steer_joint_damping}" friction="{steer_joint_friction}"/>
  </joint>

  <transmission name="joint_flw_trans_dir">
	<type>transmission_interface/SimpleTransmission</type>
    <joint name="joint_front_left_wheel_dir">
      <hardwareInterface>hardware_interface/EffortJointInterface</hardwareInterface>
    </joint>
    <actuator name="joint_flw_motor_dir">
	  <hardwareInterface>EffortJointInterface</hardwareInterface>
      <mechanicalReduction>${steer_mechanical_reduction}</mechanicalReduction>
	  <!-- motorTorqueConstant>1</motorTorqueConstant -->
	</actuator>
  </transmission>

  <!-- FRONT LEFT WHEEL (GREY) -->
  <link name="front_left_wheel">
    <inertial>
      <mass value="1.023" />
      <origin xyz="0 0 0" />
      <inertia  ixx="0.0027" ixy="0.0"  ixz="0.0"  iyy="0.0039"  iyz="0.0"  izz="0.0027" />
    </inertial>
    <visual>
       <origin xyz="0 0 0" rpy="0 0 0" />
       <geometry>
         <mesh filename="package://summit_deskribapena/meshes/wheel.dae"/>
       </geometry>
	<material name="gray">
		<color rgba="0.5 0.5 0.5 1"/>
      	</material>
    </visual>
    <collision>
       <origin xyz="0 0 0" rpy="0 0 0" />
       <geometry>
         <mesh filename="package://summit_deskribapena/meshes/wheel.dae"/>
       </geometry>
    </collision>
  </link>

  <joint name="joint_front_left_wheel" type="continuous">
    <parent link="front_left_wheel_dir"/>
    <child link="front_left_wheel"/>
    <origin xyz="0.0 0.060 0" rpy="0 0 0" />
    <axis xyz="0 1 0" rpy="0 0 0" />
    <limit effort="${wheel_joint_effort_limit}" velocity="${wheel_joint_velocity_limit}"/>
    <joint_properties damping="${wheel_joint_damping}" friction="{wheel_joint_friction}"/>
  </joint>

  <transmission name="joint_flw_trans">
	 <type>transmission_interface/SimpleTransmission</type>
     <joint name="joint_front_left_wheel">
       <hardwareInterface>hardware_interface/VelocityJointInterface</hardwareInterface>
     </joint>
     <actuator name="joint_flw_motor">
	    <hardwareInterface>VelocityJointInterface</hardwareInterface>
        <mechanicalReduction>${wheel_mechanical_reduction}</mechanicalReduction>
     	<!-- motorTorqueConstant>1</motorTorqueConstant -->
	 </actuator>
  </transmission>


<!-- DIRECTION FORWARD RIGHT     -->
<!-- =========================== -->

  <link name="front_right_wheel_dir">
    <inertial>
      <mass value="0.1" />
      <!-- center of mass (com) is defined w.r.t. link local coord system -->
      <origin xyz="0 0 0" />
      <inertia  ixx="0.01" ixy="0.0"  ixz="0.0"  iyy="0.01"  iyz="0.0"  izz="0.01" />
    </inertial>
    <visual>
       <!-- visual origin is defined w.r.t. link local coordinate system -->
       <origin xyz="0 0 0" rpy="0 0 0" />
       <geometry>
         <cylinder radius="0.015" length="0.025"/>
       </geometry>
    </visual>
    <collision>
       <!-- collision origin is defined w.r.t. link local coord. system -->
       <origin xyz="0 0 0" rpy="0 0 0 " />
       <geometry>
         <cylinder radius="0.015" length="0.025"/>
       </geometry>
    </collision>
  </link>

  <joint name="joint_front_right_wheel_dir" type="revolute">
    <parent link="base_link"/>
    <child link="front_right_wheel_dir"/>
    <origin xyz="${wheel_offset_x} -${wheel_offset_y} 0" rpy="0 0 0" />
    <axis xyz="0 0 1" rpy="0 0 0" />
    <limit effort="${steer_joint_effort_limit}" velocity="${steer_joint_velocity_limit}" lower="-0.7854" upper="0.7854"/>
    <joint_properties damping="${steer_joint_damping}" friction="{steer_joint_friction}"/>
  </joint>

  <transmission name="joint_frw_trans_dir">
	<type>transmission_interface/SimpleTransmission</type>
    <joint name="joint_front_right_wheel_dir">
      <hardwareInterface>hardware_interface/EffortJointInterface</hardwareInterface>
    </joint>
    <actuator name="joint_frw_motor_dir">
	  <hardwareInterface>EffortJointInterface</hardwareInterface>
      <mechanicalReduction>${steer_mechanical_reduction}</mechanicalReduction>
	  <!-- motorTorqueConstant>1</motorTorqueConstant -->
	</actuator>
  </transmission>


  <!-- FRONT RIGHT WHEEL (GREY) -->
  <link name="front_right_wheel">
    <inertial>
      <mass value="1.023" />
      <origin xyz="0 0 0" />
      <inertia  ixx="0.0027" ixy="0.0"  ixz="0.0"  iyy="0.0039"  iyz="0.0"  izz="0.0027" />
    </inertial>
    <visual>
       <origin xyz="0 0 0" rpy="0 0 0" />
       <geometry>
         <mesh filename="package://summit_deskribapena/meshes/wheel.dae"/>
       </geometry>
	<material name="grey">
		<color rgba="0.5 0.5 0.5 1"/>
      	</material>
    </visual>
    <collision>
       <origin xyz="0 0 0" rpy="0 0 0" />
       <geometry>
         <mesh filename="package://summit_deskribapena/meshes/wheel.dae"/>
       </geometry>
    </collision>
  </link>

  <joint name="joint_front_right_wheel" type="continuous">
    <parent link="front_right_wheel_dir"/>
    <child link="front_right_wheel"/>
    <origin xyz="0.0 -0.060 0" rpy="0 0 0" />
    <axis xyz="0 1 0" rpy="0 0 0" />
    <limit effort="${wheel_joint_effort_limit}" velocity="${wheel_joint_velocity_limit}"/>
    <joint_properties damping="${wheel_joint_damping}" friction="{wheel_joint_friction}"/>
  </joint>

  <transmission name="joint_frw_trans">
	 <type>transmission_interface/SimpleTransmission</type>
     <joint name="joint_front_right_wheel">
       <hardwareInterface>hardware_interface/VelocityJointInterface</hardwareInterface>
     </joint>
     <actuator name="joint_frw_motor">
	    <hardwareInterface>VelocityJointInterface</hardwareInterface>
        <mechanicalReduction>${wheel_mechanical_reduction}</mechanicalReduction>
     	<!-- motorTorqueConstant>1</motorTorqueConstant -->
	 </actuator>
  </transmission>





  <!-- IMU SENSOR -->
  <joint name="imu_joint" type="fixed">
      <axis xyz="1 0 0"/> <!-- 0 1 0 -->
      <origin xyz="0 0 0.2825"/>
      <parent link="base_link"/>
      <child link="imu_link"/>
  </joint>


  <link name="imu_link">
      <inertial>
        <mass value="0.001"/>
        <origin rpy="0 0 0" xyz="0 0 0"/>
        <inertia ixx="0.0001" ixy="0" ixz="0" iyy="0.000001" iyz="0" izz="0.0001"/>
      </inertial>
      <visual>
        <origin rpy="0 0 0" xyz="0 0 0"/>
        <geometry>
          <box size="0.001 0.001 0.001"/>
        </geometry>
      </visual>
      <collision>
        <origin rpy="0 0 0" xyz="0 0 0"/>
        <geometry>
          <box size=".001 .001 .001"/>
        </geometry>
      </collision>
  </link>
  

</robot>
